Workbook

Sheet How to Use
A1: BOM Master List Template — How to Use
A2: For every new project: copy this file, rename it <ProjectCode>_BOM_Rev0.xlsx, fill the header and the Lists sheet. Never start from an old project file.
A4: WHO | B4: FILLS
A5: Engineering (blue) | B5: Sub-Assembly, Discipline, Description, Part No, Manufacturer, Category, Qty/Set, Multiple, Unit, Make/Buy, Drawing/Rev, NSW Part No, PIC, Issue & Required Date
A6: Purchasing (green) | B6: Status, Supplier, PR, PO, PO Date, ETA, DO/Invoice, Qty Received, Received Date, Unit Price
A7: Assembly (orange) | B7: Qty Issued, Taken By, Date — when parts leave store to the line
A8: Auto (navy) | B8: Item No, Total Qty, Total Price, Flag — don't type
A10: STATUS | B10: Same legend as before — now a dropdown, and the row colours itself
A11: Not Finalized
A12: Finalized – Not Purchased
A13: Purchased – Not Received
A14: Received
A15: NSW Purchased
A16: New Request to NSW
A17: Cancelled
A19: FLAG | B19: MEANING
A20: NO QTY | B20: Qty/Set blank — engineer to fill
A21: NO PART NO | B21: Buy item without manufacturer P/N
A22: OVERDUE | B22: ETA passed, not received — chase supplier
A23: LATE vs REQ | B23: Supplier ETA is after the Required Date — escalate
A24: NEED PR | B24: Finalized but no PR raised
A25: SHORT | B25: Received less than Total Qty
A27: RULES
A28: 1 | B28: One row per part. Don't insert section/title rows — use the Sub-Assembly dropdown.
A29: 2 | B29: Never delete a row — set Status to Cancelled.
A30: 0 | B30: Setup: fill header (Project Name, Code, Customer) + rename sub-assemblies in Lists.
A31: 3 | B31: Design change → update Drawing Rev, note it in Remarks, add a line in Revision Log.
A32: 4 | B32: Update 'Last Updated' (BOM sheet, F6) every Monday by 12pm.
A33: 6 | B33: Don't rename or move columns — the file is designed to import into the Nix Project Tracker.
A34: 5 | B34: Customer View has no prices — still Paste Values before sending.
A37: Example row (format only — enter real rows in BOM sheet):
A38: Item | B38: Sub-Assembly | C38: Discipline | D38: Description | E38: Manufacturer Part No. | F38: Manufacturer | G38: Category | H38: Qty / Set | I38: Multiple | J38: Total Qty | K38: Unit | L38: Make / Buy | M38: Drawing No. / Rev | N38: NSW Part No. | O38: Engineer PIC | P38: Issue Date | Q38: Required Date | R38: Status | S38: Supplier | T38: PR No. | U38: PO No. | V38: PO Date | W38: ETA | X38: DO / Invoice No. | Y38: Qty Received | Z38: Received Date | AA38: Unit Price (RM) | AB38: Total Price (RM) | AC38: Qty Issued | AD38: Taken By | AE38: Issue Date (Assy) | AF38: Flag | AG38: Remarks
A39: 120-01 | B39: 120 SINGULATOR | C39: Mechanical | D39: CYLINDER | E39: CDU16-25D-M9BL | F39: SMC | G39: Pneumatic | H39: 2 | I39: 1 | J39: 2 | K39: Pcs | L39: Buy | M39: XX-120-005 Rev A | O39: HC | P39: 01-Oct-26 | Q39: 20-Oct-26 | R39: Purchased – Not Received | S39: Supplier name | T39: PR-0123 | U39: PO-0456 | V39: 03-Oct-26 | W39: 15-Oct-26 | AA39: 85 | AB39: 170 | AG39: Pick-up cylinder

Sheet BOM
A1: BOM Master List — Project Template
A2: Blue = Engineering · Green = Purchasing · Orange = Assembly · Navy = auto (don't type). One row per part, no section rows — pick Sub-Assembly from the dropdown instead.
A3: Project Name: | E3: Originator: | J3: BOM value (RM): | K3: =SUMIFS(AB11:AB410,R11:R410,"<>Cancelled") -> 0
A4: Project Code: | E4: Approval:
A5: Customer: | E5: Revision: | F5: 0
A6: Scope: | B6: All disciplines | E6: Last Updated:
A9: AUTO | B9: ENGINEERING | J9: AUTO | K9: ENGINEERING | R9: PURCHASING | AB9: AUTO | AC9: ASSEMBLY | AF9: AUTO | AG9: ENGINEERING
A10: Item | B10: Sub-Assembly | C10: Discipline | D10: Description | E10: Manufacturer Part No. | F10: Manufacturer | G10: Category | H10: Qty / Set | I10: Multiple | J10: Total Qty | K10: Unit | L10: Make / Buy | M10: Drawing No. / Rev | N10: NSW Part No. | O10: Engineer PIC | P10: Issue Date | Q10: Required Date | R10: Status | S10: Supplier | T10: PR No. | U10: PO No. | V10: PO Date | W10: ETA | X10: DO / Invoice No. | Y10: Qty Received | Z10: Received Date | AA10: Unit Price (RM) | AB10: Total Price (RM) | AC10: Qty Issued | AD10: Taken By | AE10: Issue Date (Assy) | AF10: Flag | AG10: Remarks
A11: =IF(B11="","",LEFT(B11,3)&"-"&TEXT(COUNTIF(B$11:B11,B11),"00")) | J11: =IF(H11="","",H11*IF(I11="",1,I11)) | AB11: =IF(OR(AA11="",J11=""),"",AA11*J11) | AF11: =IF(OR(D11="",R11="Cancelled"),"",IF(H11="","NO QTY",IF(AND(L11="Buy",E11=""),"NO PART NO",IF(AND(W11<>"",NOT(OR(R11="Received",R11="NSW Purchased")),W11<TODAY()),"OVERDUE",IF(AND(W11<>"",Q11<>"",W11>Q11),"LATE vs REQ",IF(AND(R11="Finalized – Not Purchased",T11=""),"NEED PR",IF(AND(Y11<>"",Y11<J11),"SHORT","")))))))
A12: =IF(B12="","",LEFT(B12,3)&"-"&TEXT(COUNTIF(B$11:B12,B12),"00")) | J12: =IF(H12="","",H12*IF(I12="",1,I12)) | AB12: =IF(OR(AA12="",J12=""),"",AA12*J12) | AF12: =IF(OR(D12="",R12="Cancelled"),"",IF(H12="","NO QTY",IF(AND(L12="Buy",E12=""),"NO PART NO",IF(AND(W12<>"",NOT(OR(R12="Received",R12="NSW Purchased")),W12<TODAY()),"OVERDUE",IF(AND(W12<>"",Q12<>"",W12>Q12),"LATE vs REQ",IF(AND(R12="Finalized – Not Purchased",T12=""),"NEED PR",IF(AND(Y12<>"",Y12<J12),"SHORT","")))))))
A13: =IF(B13="","",LEFT(B13,3)&"-"&TEXT(COUNTIF(B$11:B13,B13),"00")) | J13: =IF(H13="","",H13*IF(I13="",1,I13)) | AB13: =IF(OR(AA13="",J13=""),"",AA13*J13) | AF13: =IF(OR(D13="",R13="Cancelled"),"",IF(H13="","NO QTY",IF(AND(L13="Buy",E13=""),"NO PART NO",IF(AND(W13<>"",NOT(OR(R13="Received",R13="NSW Purchased")),W13<TODAY()),"OVERDUE",IF(AND(W13<>"",Q13<>"",W13>Q13),"LATE vs REQ",IF(AND(R13="Finalized – Not Purchased",T13=""),"NEED PR",IF(AND(Y13<>"",Y13<J13),"SHORT","")))))))
A14: =IF(B14="","",LEFT(B14,3)&"-"&TEXT(COUNTIF(B$11:B14,B14),"00")) | J14: =IF(H14="","",H14*IF(I14="",1,I14)) | AB14: =IF(OR(AA14="",J14=""),"",AA14*J14) | AF14: =IF(OR(D14="",R14="Cancelled"),"",IF(H14="","NO QTY",IF(AND(L14="Buy",E14=""),"NO PART NO",IF(AND(W14<>"",NOT(OR(R14="Received",R14="NSW Purchased")),W14<TODAY()),"OVERDUE",IF(AND(W14<>"",Q14<>"",W14>Q14),"LATE vs REQ",IF(AND(R14="Finalized – Not Purchased",T14=""),"NEED PR",IF(AND(Y14<>"",Y14<J14),"SHORT","")))))))
A15: =IF(B15="","",LEFT(B15,3)&"-"&TEXT(COUNTIF(B$11:B15,B15),"00")) | J15: =IF(H15="","",H15*IF(I15="",1,I15)) | AB15: =IF(OR(AA15="",J15=""),"",AA15*J15) | AF15: =IF(OR(D15="",R15="Cancelled"),"",IF(H15="","NO QTY",IF(AND(L15="Buy",E15=""),"NO PART NO",IF(AND(W15<>"",NOT(OR(R15="Received",R15="NSW Purchased")),W15<TODAY()),"OVERDUE",IF(AND(W15<>"",Q15<>"",W15>Q15),"LATE vs REQ",IF(AND(R15="Finalized – Not Purchased",T15=""),"NEED PR",IF(AND(Y15<>"",Y15<J15),"SHORT","")))))))
A16: =IF(B16="","",LEFT(B16,3)&"-"&TEXT(COUNTIF(B$11:B16,B16),"00")) | J16: =IF(H16="","",H16*IF(I16="",1,I16)) | AB16: =IF(OR(AA16="",J16=""),"",AA16*J16) | AF16: =IF(OR(D16="",R16="Cancelled"),"",IF(H16="","NO QTY",IF(AND(L16="Buy",E16=""),"NO PART NO",IF(AND(W16<>"",NOT(OR(R16="Received",R16="NSW Purchased")),W16<TODAY()),"OVERDUE",IF(AND(W16<>"",Q16<>"",W16>Q16),"LATE vs REQ",IF(AND(R16="Finalized – Not Purchased",T16=""),"NEED PR",IF(AND(Y16<>"",Y16<J16),"SHORT","")))))))
A17: =IF(B17="","",LEFT(B17,3)&"-"&TEXT(COUNTIF(B$11:B17,B17),"00")) | J17: =IF(H17="","",H17*IF(I17="",1,I17)) | AB17: =IF(OR(AA17="",J17=""),"",AA17*J17) | AF17: =IF(OR(D17="",R17="Cancelled"),"",IF(H17="","NO QTY",IF(AND(L17="Buy",E17=""),"NO PART NO",IF(AND(W17<>"",NOT(OR(R17="Received",R17="NSW Purchased")),W17<TODAY()),"OVERDUE",IF(AND(W17<>"",Q17<>"",W17>Q17),"LATE vs REQ",IF(AND(R17="Finalized – Not Purchased",T17=""),"NEED PR",IF(AND(Y17<>"",Y17<J17),"SHORT","")))))))
A18: =IF(B18="","",LEFT(B18,3)&"-"&TEXT(COUNTIF(B$11:B18,B18),"00")) | J18: =IF(H18="","",H18*IF(I18="",1,I18)) | AB18: =IF(OR(AA18="",J18=""),"",AA18*J18) | AF18: =IF(OR(D18="",R18="Cancelled"),"",IF(H18="","NO QTY",IF(AND(L18="Buy",E18=""),"NO PART NO",IF(AND(W18<>"",NOT(OR(R18="Received",R18="NSW Purchased")),W18<TODAY()),"OVERDUE",IF(AND(W18<>"",Q18<>"",W18>Q18),"LATE vs REQ",IF(AND(R18="Finalized – Not Purchased",T18=""),"NEED PR",IF(AND(Y18<>"",Y18<J18),"SHORT","")))))))
A19: =IF(B19="","",LEFT(B19,3)&"-"&TEXT(COUNTIF(B$11:B19,B19),"00")) | J19: =IF(H19="","",H19*IF(I19="",1,I19)) | AB19: =IF(OR(AA19="",J19=""),"",AA19*J19) | AF19: =IF(OR(D19="",R19="Cancelled"),"",IF(H19="","NO QTY",IF(AND(L19="Buy",E19=""),"NO PART NO",IF(AND(W19<>"",NOT(OR(R19="Received",R19="NSW Purchased")),W19<TODAY()),"OVERDUE",IF(AND(W19<>"",Q19<>"",W19>Q19),"LATE vs REQ",IF(AND(R19="Finalized – Not Purchased",T19=""),"NEED PR",IF(AND(Y19<>"",Y19<J19),"SHORT","")))))))
A20: =IF(B20="","",LEFT(B20,3)&"-"&TEXT(COUNTIF(B$11:B20,B20),"00")) | J20: =IF(H20="","",H20*IF(I20="",1,I20)) | AB20: =IF(OR(AA20="",J20=""),"",AA20*J20) | AF20: =IF(OR(D20="",R20="Cancelled"),"",IF(H20="","NO QTY",IF(AND(L20="Buy",E20=""),"NO PART NO",IF(AND(W20<>"",NOT(OR(R20="Received",R20="NSW Purchased")),W20<TODAY()),"OVERDUE",IF(AND(W20<>"",Q20<>"",W20>Q20),"LATE vs REQ",IF(AND(R20="Finalized – Not Purchased",T20=""),"NEED PR",IF(AND(Y20<>"",Y20<J20),"SHORT","")))))))
A21: =IF(B21="","",LEFT(B21,3)&"-"&TEXT(COUNTIF(B$11:B21,B21),"00")) | J21: =IF(H21="","",H21*IF(I21="",1,I21)) | AB21: =IF(OR(AA21="",J21=""),"",AA21*J21) | AF21: =IF(OR(D21="",R21="Cancelled"),"",IF(H21="","NO QTY",IF(AND(L21="Buy",E21=""),"NO PART NO",IF(AND(W21<>"",NOT(OR(R21="Received",R21="NSW Purchased")),W21<TODAY()),"OVERDUE",IF(AND(W21<>"",Q21<>"",W21>Q21),"LATE vs REQ",IF(AND(R21="Finalized – Not Purchased",T21=""),"NEED PR",IF(AND(Y21<>"",Y21<J21),"SHORT","")))))))
A22: =IF(B22="","",LEFT(B22,3)&"-"&TEXT(COUNTIF(B$11:B22,B22),"00")) | J22: =IF(H22="","",H22*IF(I22="",1,I22)) | AB22: =IF(OR(AA22="",J22=""),"",AA22*J22) | AF22: =IF(OR(D22="",R22="Cancelled"),"",IF(H22="","NO QTY",IF(AND(L22="Buy",E22=""),"NO PART NO",IF(AND(W22<>"",NOT(OR(R22="Received",R22="NSW Purchased")),W22<TODAY()),"OVERDUE",IF(AND(W22<>"",Q22<>"",W22>Q22),"LATE vs REQ",IF(AND(R22="Finalized – Not Purchased",T22=""),"NEED PR",IF(AND(Y22<>"",Y22<J22),"SHORT","")))))))
... A410: =IF(B410="","",LEFT(B410,3)&"-"&TEXT(COUNTIF(B$11:B410,B410),"00")) | J410: =IF(H410="","",H410*IF(I410="",1,I410)) | AB410: =IF(OR(AA410="",J410=""),"",AA410*J410) | AF410: =IF(OR(D410="",R410="Cancelled"),"",IF(H410="","NO QTY",IF(AND(L410="Buy",E410=""),"NO PART NO",IF(AND(W410<>"",NOT(OR(R410="Received",R410="NSW Purchased")),W410<TODAY()),"OVERDUE",IF(AND(W410<>"",Q410<>"",W410>Q410),"LATE vs REQ",IF(AND(R410="Finalized – Not Purchased",T410=""),"NEED PR",IF(AND(Y410<>"",Y410<J410),"SHORT","")))))))

Sheet Progress
A1: BOM Progress Dashboard
A2: Auto from BOM. Finalized = any status past 'Not Finalized'. Ordered = Purchased–Not Received / Received / NSW Purchased. Cancelled excluded. Cost columns are INTERNAL.
A4: OVERALL
A5: BOM lines | C5: Finalized | E5: Ordered | G5: Received | I5: Overdue | K5: Lines with flags
A6: =B26 -> 0 | C6: =C26 -> 0 | E6: =E26 -> 0 | G6: =G26 -> 0 | I6: =I26 -> 0 | K6: =J26 -> 0
C7: =D26 -> 0 | E7: =F26 -> 0 | G7: =H26 -> 0
A9: By Sub-Assembly
A10: Group | B10: Lines | C10: Finalized | D10: % Final | E10: Ordered | F10: % Ordered | G10: Received | H10: % Rcvd | I10: Overdue | J10: Flags (any) | K10: Value (RM)
A11: =Lists!$A$5 -> 110 BASE & STRUCTURE | B11: =COUNTIFS(BOM!$B$11:$B$410,$A11,BOM!$D$11:$D$410,"<>",BOM!$R$11:$R$410,"<>Cancelled") -> 0 | C11: =COUNTIFS(BOM!$B$11:$B$410,$A11,BOM!$D$11:$D$410,"<>",BOM!$R$11:$R$410,"<>Cancelled")-COUNTIFS(BOM!$B$11:$B$410,$A11,BOM!$D$11:$D$410,"<>",BOM!$R$11:$R$410,"Not Finalized")-COUNTIFS(BOM!$B$11:$B$410,$A11,BOM!$D$11:$D$410,"<>",BOM!$R$11:$R$410,"") -> 0 | D11: =IF($B11=0,0,C11/$B11) -> 0 | E11: =COUNTIFS(BOM!$B$11:$B$410,$A11,BOM!$D$11:$D$410,"<>",BOM!$R$11:$R$410,"Purchased – Not Received")+COUNTIFS(BOM!$B$11:$B$410,$A11,BOM!$D$11:$D$410,"<>",BOM!$R$11:$R$410,"Received")+COUNTIFS(BOM!$B$11:$B$410,$A11,BOM!$D$11:$D$410,"<>",BOM!$R$11:$R$410,"NSW Purchased") -> 0 | F11: =IF($B11=0,0,E11/$B11) -> 0 | G11: =COUNTIFS(BOM!$B$11:$B$410,$A11,BOM!$D$11:$D$410,"<>",BOM!$R$11:$R$410,"Received")+COUNTIFS(BOM!$B$11:$B$410,$A11,BOM!$D$11:$D$410,"<>",BOM!$R$11:$R$410,"NSW Purchased") -> 0 | H11: =IF($B11=0,0,G11/$B11) -> 0 | I11: =COUNTIFS(BOM!$B$11:$B$410,$A11,BOM!$AF$11:$AF$410,"OVERDUE") -> 0 | J11: =COUNTIFS(BOM!$B$11:$B$410,$A11,BOM!$AF$11:$AF$410,"?*") -> 0 | K11: =SUMIFS(BOM!$AB$11:$AB$410,BOM!$B$11:$B$410,$A11,BOM!$R$11:$R$410,"<>Cancelled") -> 0
A12: =Lists!$A$6 -> 120 (rename) | B12: =COUNTIFS(BOM!$B$11:$B$410,$A12,BOM!$D$11:$D$410,"<>",BOM!$R$11:$R$410,"<>Cancelled") -> 0 | C12: =COUNTIFS(BOM!$B$11:$B$410,$A12,BOM!$D$11:$D$410,"<>",BOM!$R$11:$R$410,"<>Cancelled")-COUNTIFS(BOM!$B$11:$B$410,$A12,BOM!$D$11:$D$410,"<>",BOM!$R$11:$R$410,"Not Finalized")-COUNTIFS(BOM!$B$11:$B$410,$A12,BOM!$D$11:$D$410,"<>",BOM!$R$11:$R$410,"") -> 0 | D12: =IF($B12=0,0,C12/$B12) -> 0 | E12: =COUNTIFS(BOM!$B$11:$B$410,$A12,BOM!$D$11:$D$410,"<>",BOM!$R$11:$R$410,"Purchased – Not Received")+COUNTIFS(BOM!$B$11:$B$410,$A12,BOM!$D$11:$D$410,"<>",BOM!$R$11:$R$410,"Received")+COUNTIFS(BOM!$B$11:$B$410,$A12,BOM!$D$11:$D$410,"<>",BOM!$R$11:$R$410,"NSW Purchased") -> 0 | F12: =IF($B12=0,0,E12/$B12) -> 0 | G12: =COUNTIFS(BOM!$B$11:$B$410,$A12,BOM!$D$11:$D$410,"<>",BOM!$R$11:$R$410,"Received")+COUNTIFS(BOM!$B$11:$B$410,$A12,BOM!$D$11:$D$410,"<>",BOM!$R$11:$R$410,"NSW Purchased") -> 0 | H12: =IF($B12=0,0,G12/$B12) -> 0 | I12: =COUNTIFS(BOM!$B$11:$B$410,$A12,BOM!$AF$11:$AF$410,"OVERDUE") -> 0 | J12: =COUNTIFS(BOM!$B$11:$B$410,$A12,BOM!$AF$11:$AF$410,"?*") -> 0 | K12: =SUMIFS(BOM!$AB$11:$AB$410,BOM!$B$11:$B$410,$A12,BOM!$R$11:$R$410,"<>Cancelled") -> 0
A13: =Lists!$A$7 -> 130 (rename) | B13: =COUNTIFS(BOM!$B$11:$B$410,$A13,BOM!$D$11:$D$410,"<>",BOM!$R$11:$R$410,"<>Cancelled") -> 0 | C13: =COUNTIFS(BOM!$B$11:$B$410,$A13,BOM!$D$11:$D$410,"<>",BOM!$R$11:$R$410,"<>Cancelled")-COUNTIFS(BOM!$B$11:$B$410,$A13,BOM!$D$11:$D$410,"<>",BOM!$R$11:$R$410,"Not Finalized")-COUNTIFS(BOM!$B$11:$B$410,$A13,BOM!$D$11:$D$410,"<>",BOM!$R$11:$R$410,"") -> 0 | D13: =IF($B13=0,0,C13/$B13) -> 0 | E13: =COUNTIFS(BOM!$B$11:$B$410,$A13,BOM!$D$11:$D$410,"<>",BOM!$R$11:$R$410,"Purchased – Not Received")+COUNTIFS(BOM!$B$11:$B$410,$A13,BOM!$D$11:$D$410,"<>",BOM!$R$11:$R$410,"Received")+COUNTIFS(BOM!$B$11:$B$410,$A13,BOM!$D$11:$D$410,"<>",BOM!$R$11:$R$410,"NSW Purchased") -> 0 | F13: =IF($B13=0,0,E13/$B13) -> 0 | G13: =COUNTIFS(BOM!$B$11:$B$410,$A13,BOM!$D$11:$D$410,"<>",BOM!$R$11:$R$410,"Received")+COUNTIFS(BOM!$B$11:$B$410,$A13,BOM!$D$11:$D$410,"<>",BOM!$R$11:$R$410,"NSW Purchased") -> 0 | H13: =IF($B13=0,0,G13/$B13) -> 0 | I13: =COUNTIFS(BOM!$B$11:$B$410,$A13,BOM!$AF$11:$AF$410,"OVERDUE") -> 0 | J13: =COUNTIFS(BOM!$B$11:$B$410,$A13,BOM!$AF$11:$AF$410,"?*") -> 0 | K13: =SUMIFS(BOM!$AB$11:$AB$410,BOM!$B$11:$B$410,$A13,BOM!$R$11:$R$410,"<>Cancelled") -> 0
A14: =Lists!$A$8 -> 140 (rename) | B14: =COUNTIFS(BOM!$B$11:$B$410,$A14,BOM!$D$11:$D$410,"<>",BOM!$R$11:$R$410,"<>Cancelled") -> 0 | C14: =COUNTIFS(BOM!$B$11:$B$410,$A14,BOM!$D$11:$D$410,"<>",BOM!$R$11:$R$410,"<>Cancelled")-COUNTIFS(BOM!$B$11:$B$410,$A14,BOM!$D$11:$D$410,"<>",BOM!$R$11:$R$410,"Not Finalized")-COUNTIFS(BOM!$B$11:$B$410,$A14,BOM!$D$11:$D$410,"<>",BOM!$R$11:$R$410,"") -> 0 | D14: =IF($B14=0,0,C14/$B14) -> 0 | E14: =COUNTIFS(BOM!$B$11:$B$410,$A14,BOM!$D$11:$D$410,"<>",BOM!$R$11:$R$410,"Purchased – Not Received")+COUNTIFS(BOM!$B$11:$B$410,$A14,BOM!$D$11:$D$410,"<>",BOM!$R$11:$R$410,"Received")+COUNTIFS(BOM!$B$11:$B$410,$A14,BOM!$D$11:$D$410,"<>",BOM!$R$11:$R$410,"NSW Purchased") -> 0 | F14: =IF($B14=0,0,E14/$B14) -> 0 | G14: =COUNTIFS(BOM!$B$11:$B$410,$A14,BOM!$D$11:$D$410,"<>",BOM!$R$11:$R$410,"Received")+COUNTIFS(BOM!$B$11:$B$410,$A14,BOM!$D$11:$D$410,"<>",BOM!$R$11:$R$410,"NSW Purchased") -> 0 | H14: =IF($B14=0,0,G14/$B14) -> 0 | I14: =COUNTIFS(BOM!$B$11:$B$410,$A14,BOM!$AF$11:$AF$410,"OVERDUE") -> 0 | J14: =COUNTIFS(BOM!$B$11:$B$410,$A14,BOM!$AF$11:$AF$410,"?*") -> 0 | K14: =SUMIFS(BOM!$AB$11:$AB$410,BOM!$B$11:$B$410,$A14,BOM!$R$11:$R$410,"<>Cancelled") -> 0
A15: =Lists!$A$9 -> 150 (rename) | B15: =COUNTIFS(BOM!$B$11:$B$410,$A15,BOM!$D$11:$D$410,"<>",BOM!$R$11:$R$410,"<>Cancelled") -> 0 | C15: =COUNTIFS(BOM!$B$11:$B$410,$A15,BOM!$D$11:$D$410,"<>",BOM!$R$11:$R$410,"<>Cancelled")-COUNTIFS(BOM!$B$11:$B$410,$A15,BOM!$D$11:$D$410,"<>",BOM!$R$11:$R$410,"Not Finalized")-COUNTIFS(BOM!$B$11:$B$410,$A15,BOM!$D$11:$D$410,"<>",BOM!$R$11:$R$410,"") -> 0 | D15: =IF($B15=0,0,C15/$B15) -> 0 | E15: =COUNTIFS(BOM!$B$11:$B$410,$A15,BOM!$D$11:$D$410,"<>",BOM!$R$11:$R$410,"Purchased – Not Received")+COUNTIFS(BOM!$B$11:$B$410,$A15,BOM!$D$11:$D$410,"<>",BOM!$R$11:$R$410,"Received")+COUNTIFS(BOM!$B$11:$B$410,$A15,BOM!$D$11:$D$410,"<>",BOM!$R$11:$R$410,"NSW Purchased") -> 0 | F15: =IF($B15=0,0,E15/$B15) -> 0 | G15: =COUNTIFS(BOM!$B$11:$B$410,$A15,BOM!$D$11:$D$410,"<>",BOM!$R$11:$R$410,"Received")+COUNTIFS(BOM!$B$11:$B$410,$A15,BOM!$D$11:$D$410,"<>",BOM!$R$11:$R$410,"NSW Purchased") -> 0 | H15: =IF($B15=0,0,G15/$B15) -> 0 | I15: =COUNTIFS(BOM!$B$11:$B$410,$A15,BOM!$AF$11:$AF$410,"OVERDUE") -> 0 | J15: =COUNTIFS(BOM!$B$11:$B$410,$A15,BOM!$AF$11:$AF$410,"?*") -> 0 | K15: =SUMIFS(BOM!$AB$11:$AB$410,BOM!$B$11:$B$410,$A15,BOM!$R$11:$R$410,"<>Cancelled") -> 0
A16: =Lists!$A$10 -> 160 (rename) | B16: =COUNTIFS(BOM!$B$11:$B$410,$A16,BOM!$D$11:$D$410,"<>",BOM!$R$11:$R$410,"<>Cancelled") -> 0 | C16: =COUNTIFS(BOM!$B$11:$B$410,$A16,BOM!$D$11:$D$410,"<>",BOM!$R$11:$R$410,"<>Cancelled")-COUNTIFS(BOM!$B$11:$B$410,$A16,BOM!$D$11:$D$410,"<>",BOM!$R$11:$R$410,"Not Finalized")-COUNTIFS(BOM!$B$11:$B$410,$A16,BOM!$D$11:$D$410,"<>",BOM!$R$11:$R$410,"") -> 0 | D16: =IF($B16=0,0,C16/$B16) -> 0 | E16: =COUNTIFS(BOM!$B$11:$B$410,$A16,BOM!$D$11:$D$410,"<>",BOM!$R$11:$R$410,"Purchased – Not Received")+COUNTIFS(BOM!$B$11:$B$410,$A16,BOM!$D$11:$D$410,"<>",BOM!$R$11:$R$410,"Received")+COUNTIFS(BOM!$B$11:$B$410,$A16,BOM!$D$11:$D$410,"<>",BOM!$R$11:$R$410,"NSW Purchased") -> 0 | F16: =IF($B16=0,0,E16/$B16) -> 0 | G16: =COUNTIFS(BOM!$B$11:$B$410,$A16,BOM!$D$11:$D$410,"<>",BOM!$R$11:$R$410,"Received")+COUNTIFS(BOM!$B$11:$B$410,$A16,BOM!$D$11:$D$410,"<>",BOM!$R$11:$R$410,"NSW Purchased") -> 0 | H16: =IF($B16=0,0,G16/$B16) -> 0 | I16: =COUNTIFS(BOM!$B$11:$B$410,$A16,BOM!$AF$11:$AF$410,"OVERDUE") -> 0 | J16: =COUNTIFS(BOM!$B$11:$B$410,$A16,BOM!$AF$11:$AF$410,"?*") -> 0 | K16: =SUMIFS(BOM!$AB$11:$AB$410,BOM!$B$11:$B$410,$A16,BOM!$R$11:$R$410,"<>Cancelled") -> 0
A17: =Lists!$A$11 -> 170 (rename) | B17: =COUNTIFS(BOM!$B$11:$B$410,$A17,BOM!$D$11:$D$410,"<>",BOM!$R$11:$R$410,"<>Cancelled") -> 0 | C17: =COUNTIFS(BOM!$B$11:$B$410,$A17,BOM!$D$11:$D$410,"<>",BOM!$R$11:$R$410,"<>Cancelled")-COUNTIFS(BOM!$B$11:$B$410,$A17,BOM!$D$11:$D$410,"<>",BOM!$R$11:$R$410,"Not Finalized")-COUNTIFS(BOM!$B$11:$B$410,$A17,BOM!$D$11:$D$410,"<>",BOM!$R$11:$R$410,"") -> 0 | D17: =IF($B17=0,0,C17/$B17) -> 0 | E17: =COUNTIFS(BOM!$B$11:$B$410,$A17,BOM!$D$11:$D$410,"<>",BOM!$R$11:$R$410,"Purchased – Not Received")+COUNTIFS(BOM!$B$11:$B$410,$A17,BOM!$D$11:$D$410,"<>",BOM!$R$11:$R$410,"Received")+COUNTIFS(BOM!$B$11:$B$410,$A17,BOM!$D$11:$D$410,"<>",BOM!$R$11:$R$410,"NSW Purchased") -> 0 | F17: =IF($B17=0,0,E17/$B17) -> 0 | G17: =COUNTIFS(BOM!$B$11:$B$410,$A17,BOM!$D$11:$D$410,"<>",BOM!$R$11:$R$410,"Received")+COUNTIFS(BOM!$B$11:$B$410,$A17,BOM!$D$11:$D$410,"<>",BOM!$R$11:$R$410,"NSW Purchased") -> 0 | H17: =IF($B17=0,0,G17/$B17) -> 0 | I17: =COUNTIFS(BOM!$B$11:$B$410,$A17,BOM!$AF$11:$AF$410,"OVERDUE") -> 0 | J17: =COUNTIFS(BOM!$B$11:$B$410,$A17,BOM!$AF$11:$AF$410,"?*") -> 0 | K17: =SUMIFS(BOM!$AB$11:$AB$410,BOM!$B$11:$B$410,$A17,BOM!$R$11:$R$410,"<>Cancelled") -> 0
A18: =Lists!$A$12 -> 180 (rename) | B18: =COUNTIFS(BOM!$B$11:$B$410,$A18,BOM!$D$11:$D$410,"<>",BOM!$R$11:$R$410,"<>Cancelled") -> 0 | C18: =COUNTIFS(BOM!$B$11:$B$410,$A18,BOM!$D$11:$D$410,"<>",BOM!$R$11:$R$410,"<>Cancelled")-COUNTIFS(BOM!$B$11:$B$410,$A18,BOM!$D$11:$D$410,"<>",BOM!$R$11:$R$410,"Not Finalized")-COUNTIFS(BOM!$B$11:$B$410,$A18,BOM!$D$11:$D$410,"<>",BOM!$R$11:$R$410,"") -> 0 | D18: =IF($B18=0,0,C18/$B18) -> 0 | E18: =COUNTIFS(BOM!$B$11:$B$410,$A18,BOM!$D$11:$D$410,"<>",BOM!$R$11:$R$410,"Purchased – Not Received")+COUNTIFS(BOM!$B$11:$B$410,$A18,BOM!$D$11:$D$410,"<>",BOM!$R$11:$R$410,"Received")+COUNTIFS(BOM!$B$11:$B$410,$A18,BOM!$D$11:$D$410,"<>",BOM!$R$11:$R$410,"NSW Purchased") -> 0 | F18: =IF($B18=0,0,E18/$B18) -> 0 | G18: =COUNTIFS(BOM!$B$11:$B$410,$A18,BOM!$D$11:$D$410,"<>",BOM!$R$11:$R$410,"Received")+COUNTIFS(BOM!$B$11:$B$410,$A18,BOM!$D$11:$D$410,"<>",BOM!$R$11:$R$410,"NSW Purchased") -> 0 | H18: =IF($B18=0,0,G18/$B18) -> 0 | I18: =COUNTIFS(BOM!$B$11:$B$410,$A18,BOM!$AF$11:$AF$410,"OVERDUE") -> 0 | J18: =COUNTIFS(BOM!$B$11:$B$410,$A18,BOM!$AF$11:$AF$410,"?*") -> 0 | K18: =SUMIFS(BOM!$AB$11:$AB$410,BOM!$B$11:$B$410,$A18,BOM!$R$11:$R$410,"<>Cancelled") -> 0
A19: =Lists!$A$13 -> 190 (rename) | B19: =COUNTIFS(BOM!$B$11:$B$410,$A19,BOM!$D$11:$D$410,"<>",BOM!$R$11:$R$410,"<>Cancelled") -> 0 | C19: =COUNTIFS(BOM!$B$11:$B$410,$A19,BOM!$D$11:$D$410,"<>",BOM!$R$11:$R$410,"<>Cancelled")-COUNTIFS(BOM!$B$11:$B$410,$A19,BOM!$D$11:$D$410,"<>",BOM!$R$11:$R$410,"Not Finalized")-COUNTIFS(BOM!$B$11:$B$410,$A19,BOM!$D$11:$D$410,"<>",BOM!$R$11:$R$410,"") -> 0 | D19: =IF($B19=0,0,C19/$B19) -> 0 | E19: =COUNTIFS(BOM!$B$11:$B$410,$A19,BOM!$D$11:$D$410,"<>",BOM!$R$11:$R$410,"Purchased – Not Received")+COUNTIFS(BOM!$B$11:$B$410,$A19,BOM!$D$11:$D$410,"<>",BOM!$R$11:$R$410,"Received")+COUNTIFS(BOM!$B$11:$B$410,$A19,BOM!$D$11:$D$410,"<>",BOM!$R$11:$R$410,"NSW Purchased") -> 0 | F19: =IF($B19=0,0,E19/$B19) -> 0 | G19: =COUNTIFS(BOM!$B$11:$B$410,$A19,BOM!$D$11:$D$410,"<>",BOM!$R$11:$R$410,"Received")+COUNTIFS(BOM!$B$11:$B$410,$A19,BOM!$D$11:$D$410,"<>",BOM!$R$11:$R$410,"NSW Purchased") -> 0 | H19: =IF($B19=0,0,G19/$B19) -> 0 | I19: =COUNTIFS(BOM!$B$11:$B$410,$A19,BOM!$AF$11:$AF$410,"OVERDUE") -> 0 | J19: =COUNTIFS(BOM!$B$11:$B$410,$A19,BOM!$AF$11:$AF$410,"?*") -> 0 | K19: =SUMIFS(BOM!$AB$11:$AB$410,BOM!$B$11:$B$410,$A19,BOM!$R$11:$R$410,"<>Cancelled") -> 0
A20: =Lists!$A$14 -> 200 (rename) | B20: =COUNTIFS(BOM!$B$11:$B$410,$A20,BOM!$D$11:$D$410,"<>",BOM!$R$11:$R$410,"<>Cancelled") -> 0 | C20: =COUNTIFS(BOM!$B$11:$B$410,$A20,BOM!$D$11:$D$410,"<>",BOM!$R$11:$R$410,"<>Cancelled")-COUNTIFS(BOM!$B$11:$B$410,$A20,BOM!$D$11:$D$410,"<>",BOM!$R$11:$R$410,"Not Finalized")-COUNTIFS(BOM!$B$11:$B$410,$A20,BOM!$D$11:$D$410,"<>",BOM!$R$11:$R$410,"") -> 0 | D20: =IF($B20=0,0,C20/$B20) -> 0 | E20: =COUNTIFS(BOM!$B$11:$B$410,$A20,BOM!$D$11:$D$410,"<>",BOM!$R$11:$R$410,"Purchased – Not Received")+COUNTIFS(BOM!$B$11:$B$410,$A20,BOM!$D$11:$D$410,"<>",BOM!$R$11:$R$410,"Received")+COUNTIFS(BOM!$B$11:$B$410,$A20,BOM!$D$11:$D$410,"<>",BOM!$R$11:$R$410,"NSW Purchased") -> 0 | F20: =IF($B20=0,0,E20/$B20) -> 0 | G20: =COUNTIFS(BOM!$B$11:$B$410,$A20,BOM!$D$11:$D$410,"<>",BOM!$R$11:$R$410,"Received")+COUNTIFS(BOM!$B$11:$B$410,$A20,BOM!$D$11:$D$410,"<>",BOM!$R$11:$R$410,"NSW Purchased") -> 0 | H20: =IF($B20=0,0,G20/$B20) -> 0 | I20: =COUNTIFS(BOM!$B$11:$B$410,$A20,BOM!$AF$11:$AF$410,"OVERDUE") -> 0 | J20: =COUNTIFS(BOM!$B$11:$B$410,$A20,BOM!$AF$11:$AF$410,"?*") -> 0 | K20: =SUMIFS(BOM!$AB$11:$AB$410,BOM!$B$11:$B$410,$A20,BOM!$R$11:$R$410,"<>Cancelled") -> 0
A21: =Lists!$A$15 -> 210 (rename) | B21: =COUNTIFS(BOM!$B$11:$B$410,$A21,BOM!$D$11:$D$410,"<>",BOM!$R$11:$R$410,"<>Cancelled") -> 0 | C21: =COUNTIFS(BOM!$B$11:$B$410,$A21,BOM!$D$11:$D$410,"<>",BOM!$R$11:$R$410,"<>Cancelled")-COUNTIFS(BOM!$B$11:$B$410,$A21,BOM!$D$11:$D$410,"<>",BOM!$R$11:$R$410,"Not Finalized")-COUNTIFS(BOM!$B$11:$B$410,$A21,BOM!$D$11:$D$410,"<>",BOM!$R$11:$R$410,"") -> 0 | D21: =IF($B21=0,0,C21/$B21) -> 0 | E21: =COUNTIFS(BOM!$B$11:$B$410,$A21,BOM!$D$11:$D$410,"<>",BOM!$R$11:$R$410,"Purchased – Not Received")+COUNTIFS(BOM!$B$11:$B$410,$A21,BOM!$D$11:$D$410,"<>",BOM!$R$11:$R$410,"Received")+COUNTIFS(BOM!$B$11:$B$410,$A21,BOM!$D$11:$D$410,"<>",BOM!$R$11:$R$410,"NSW Purchased") -> 0 | F21: =IF($B21=0,0,E21/$B21) -> 0 | G21: =COUNTIFS(BOM!$B$11:$B$410,$A21,BOM!$D$11:$D$410,"<>",BOM!$R$11:$R$410,"Received")+COUNTIFS(BOM!$B$11:$B$410,$A21,BOM!$D$11:$D$410,"<>",BOM!$R$11:$R$410,"NSW Purchased") -> 0 | H21: =IF($B21=0,0,G21/$B21) -> 0 | I21: =COUNTIFS(BOM!$B$11:$B$410,$A21,BOM!$AF$11:$AF$410,"OVERDUE") -> 0 | J21: =COUNTIFS(BOM!$B$11:$B$410,$A21,BOM!$AF$11:$AF$410,"?*") -> 0 | K21: =SUMIFS(BOM!$AB$11:$AB$410,BOM!$B$11:$B$410,$A21,BOM!$R$11:$R$410,"<>Cancelled") -> 0
A22: =Lists!$A$16 -> 220 (rename) | B22: =COUNTIFS(BOM!$B$11:$B$410,$A22,BOM!$D$11:$D$410,"<>",BOM!$R$11:$R$410,"<>Cancelled") -> 0 | C22: =COUNTIFS(BOM!$B$11:$B$410,$A22,BOM!$D$11:$D$410,"<>",BOM!$R$11:$R$410,"<>Cancelled")-COUNTIFS(BOM!$B$11:$B$410,$A22,BOM!$D$11:$D$410,"<>",BOM!$R$11:$R$410,"Not Finalized")-COUNTIFS(BOM!$B$11:$B$410,$A22,BOM!$D$11:$D$410,"<>",BOM!$R$11:$R$410,"") -> 0 | D22: =IF($B22=0,0,C22/$B22) -> 0 | E22: =COUNTIFS(BOM!$B$11:$B$410,$A22,BOM!$D$11:$D$410,"<>",BOM!$R$11:$R$410,"Purchased – Not Received")+COUNTIFS(BOM!$B$11:$B$410,$A22,BOM!$D$11:$D$410,"<>",BOM!$R$11:$R$410,"Received")+COUNTIFS(BOM!$B$11:$B$410,$A22,BOM!$D$11:$D$410,"<>",BOM!$R$11:$R$410,"NSW Purchased") -> 0 | F22: =IF($B22=0,0,E22/$B22) -> 0 | G22: =COUNTIFS(BOM!$B$11:$B$410,$A22,BOM!$D$11:$D$410,"<>",BOM!$R$11:$R$410,"Received")+COUNTIFS(BOM!$B$11:$B$410,$A22,BOM!$D$11:$D$410,"<>",BOM!$R$11:$R$410,"NSW Purchased") -> 0 | H22: =IF($B22=0,0,G22/$B22) -> 0 | I22: =COUNTIFS(BOM!$B$11:$B$410,$A22,BOM!$AF$11:$AF$410,"OVERDUE") -> 0 | J22: =COUNTIFS(BOM!$B$11:$B$410,$A22,BOM!$AF$11:$AF$410,"?*") -> 0 | K22: =SUMIFS(BOM!$AB$11:$AB$410,BOM!$B$11:$B$410,$A22,BOM!$R$11:$R$410,"<>Cancelled") -> 0
A23: =Lists!$A$17 -> 230 (rename) | B23: =COUNTIFS(BOM!$B$11:$B$410,$A23,BOM!$D$11:$D$410,"<>",BOM!$R$11:$R$410,"<>Cancelled") -> 0 | C23: =COUNTIFS(BOM!$B$11:$B$410,$A23,BOM!$D$11:$D$410,"<>",BOM!$R$11:$R$410,"<>Cancelled")-COUNTIFS(BOM!$B$11:$B$410,$A23,BOM!$D$11:$D$410,"<>",BOM!$R$11:$R$410,"Not Finalized")-COUNTIFS(BOM!$B$11:$B$410,$A23,BOM!$D$11:$D$410,"<>",BOM!$R$11:$R$410,"") -> 0 | D23: =IF($B23=0,0,C23/$B23) -> 0 | E23: =COUNTIFS(BOM!$B$11:$B$410,$A23,BOM!$D$11:$D$410,"<>",BOM!$R$11:$R$410,"Purchased – Not Received")+COUNTIFS(BOM!$B$11:$B$410,$A23,BOM!$D$11:$D$410,"<>",BOM!$R$11:$R$410,"Received")+COUNTIFS(BOM!$B$11:$B$410,$A23,BOM!$D$11:$D$410,"<>",BOM!$R$11:$R$410,"NSW Purchased") -> 0 | F23: =IF($B23=0,0,E23/$B23) -> 0 | G23: =COUNTIFS(BOM!$B$11:$B$410,$A23,BOM!$D$11:$D$410,"<>",BOM!$R$11:$R$410,"Received")+COUNTIFS(BOM!$B$11:$B$410,$A23,BOM!$D$11:$D$410,"<>",BOM!$R$11:$R$410,"NSW Purchased") -> 0 | H23: =IF($B23=0,0,G23/$B23) -> 0 | I23: =COUNTIFS(BOM!$B$11:$B$410,$A23,BOM!$AF$11:$AF$410,"OVERDUE") -> 0 | J23: =COUNTIFS(BOM!$B$11:$B$410,$A23,BOM!$AF$11:$AF$410,"?*") -> 0 | K23: =SUMIFS(BOM!$AB$11:$AB$410,BOM!$B$11:$B$410,$A23,BOM!$R$11:$R$410,"<>Cancelled") -> 0
A24: =Lists!$A$18 -> 240 (rename) | B24: =COUNTIFS(BOM!$B$11:$B$410,$A24,BOM!$D$11:$D$410,"<>",BOM!$R$11:$R$410,"<>Cancelled") -> 0 | C24: =COUNTIFS(BOM!$B$11:$B$410,$A24,BOM!$D$11:$D$410,"<>",BOM!$R$11:$R$410,"<>Cancelled")-COUNTIFS(BOM!$B$11:$B$410,$A24,BOM!$D$11:$D$410,"<>",BOM!$R$11:$R$410,"Not Finalized")-COUNTIFS(BOM!$B$11:$B$410,$A24,BOM!$D$11:$D$410,"<>",BOM!$R$11:$R$410,"") -> 0 | D24: =IF($B24=0,0,C24/$B24) -> 0 | E24: =COUNTIFS(BOM!$B$11:$B$410,$A24,BOM!$D$11:$D$410,"<>",BOM!$R$11:$R$410,"Purchased – Not Received")+COUNTIFS(BOM!$B$11:$B$410,$A24,BOM!$D$11:$D$410,"<>",BOM!$R$11:$R$410,"Received")+COUNTIFS(BOM!$B$11:$B$410,$A24,BOM!$D$11:$D$410,"<>",BOM!$R$11:$R$410,"NSW Purchased") -> 0 | F24: =IF($B24=0,0,E24/$B24) -> 0 | G24: =COUNTIFS(BOM!$B$11:$B$410,$A24,BOM!$D$11:$D$410,"<>",BOM!$R$11:$R$410,"Received")+COUNTIFS(BOM!$B$11:$B$410,$A24,BOM!$D$11:$D$410,"<>",BOM!$R$11:$R$410,"NSW Purchased") -> 0 | H24: =IF($B24=0,0,G24/$B24) -> 0 | I24: =COUNTIFS(BOM!$B$11:$B$410,$A24,BOM!$AF$11:$AF$410,"OVERDUE") -> 0 | J24: =COUNTIFS(BOM!$B$11:$B$410,$A24,BOM!$AF$11:$AF$410,"?*") -> 0 | K24: =SUMIFS(BOM!$AB$11:$AB$410,BOM!$B$11:$B$410,$A24,BOM!$R$11:$R$410,"<>Cancelled") -> 0
A25: =Lists!$A$19 -> 250 (rename) | B25: =COUNTIFS(BOM!$B$11:$B$410,$A25,BOM!$D$11:$D$410,"<>",BOM!$R$11:$R$410,"<>Cancelled") -> 0 | C25: =COUNTIFS(BOM!$B$11:$B$410,$A25,BOM!$D$11:$D$410,"<>",BOM!$R$11:$R$410,"<>Cancelled")-COUNTIFS(BOM!$B$11:$B$410,$A25,BOM!$D$11:$D$410,"<>",BOM!$R$11:$R$410,"Not Finalized")-COUNTIFS(BOM!$B$11:$B$410,$A25,BOM!$D$11:$D$410,"<>",BOM!$R$11:$R$410,"") -> 0 | D25: =IF($B25=0,0,C25/$B25) -> 0 | E25: =COUNTIFS(BOM!$B$11:$B$410,$A25,BOM!$D$11:$D$410,"<>",BOM!$R$11:$R$410,"Purchased – Not Received")+COUNTIFS(BOM!$B$11:$B$410,$A25,BOM!$D$11:$D$410,"<>",BOM!$R$11:$R$410,"Received")+COUNTIFS(BOM!$B$11:$B$410,$A25,BOM!$D$11:$D$410,"<>",BOM!$R$11:$R$410,"NSW Purchased") -> 0 | F25: =IF($B25=0,0,E25/$B25) -> 0 | G25: =COUNTIFS(BOM!$B$11:$B$410,$A25,BOM!$D$11:$D$410,"<>",BOM!$R$11:$R$410,"Received")+COUNTIFS(BOM!$B$11:$B$410,$A25,BOM!$D$11:$D$410,"<>",BOM!$R$11:$R$410,"NSW Purchased") -> 0 | H25: =IF($B25=0,0,G25/$B25) -> 0 | I25: =COUNTIFS(BOM!$B$11:$B$410,$A25,BOM!$AF$11:$AF$410,"OVERDUE") -> 0 | J25: =COUNTIFS(BOM!$B$11:$B$410,$A25,BOM!$AF$11:$AF$410,"?*") -> 0 | K25: =SUMIFS(BOM!$AB$11:$AB$410,BOM!$B$11:$B$410,$A25,BOM!$R$11:$R$410,"<>Cancelled") -> 0
A26: TOTAL | B26: =SUM(B11:B25) -> 0 | C26: =SUM(C11:C25) -> 0 | D26: =IF($B26=0,0,C26/$B26) -> 0 | E26: =SUM(E11:E25) -> 0 | F26: =IF($B26=0,0,E26/$B26) -> 0 | G26: =SUM(G11:G25) -> 0 | H26: =IF($B26=0,0,G26/$B26) -> 0 | I26: =SUM(I11:I25) -> 0 | J26: =SUM(J11:J25) -> 0 | K26: =SUM(K11:K25) -> 0
A28: By Discipline
A29: Group | B29: Lines | C29: Finalized | D29: % Final | E29: Ordered | F29: % Ordered | G29: Received | H29: % Rcvd | I29: Overdue | J29: Flags (any) | K29: Value (RM)
A30: =Lists!$B$5 -> Mechanical | B30: =COUNTIFS(BOM!$C$11:$C$410,$A30,BOM!$D$11:$D$410,"<>",BOM!$R$11:$R$410,"<>Cancelled") -> 0 | C30: =COUNTIFS(BOM!$C$11:$C$410,$A30,BOM!$D$11:$D$410,"<>",BOM!$R$11:$R$410,"<>Cancelled")-COUNTIFS(BOM!$C$11:$C$410,$A30,BOM!$D$11:$D$410,"<>",BOM!$R$11:$R$410,"Not Finalized")-COUNTIFS(BOM!$C$11:$C$410,$A30,BOM!$D$11:$D$410,"<>",BOM!$R$11:$R$410,"") -> 0 | D30: =IF($B30=0,0,C30/$B30) -> 0 | E30: =COUNTIFS(BOM!$C$11:$C$410,$A30,BOM!$D$11:$D$410,"<>",BOM!$R$11:$R$410,"Purchased – Not Received")+COUNTIFS(BOM!$C$11:$C$410,$A30,BOM!$D$11:$D$410,"<>",BOM!$R$11:$R$410,"Received")+COUNTIFS(BOM!$C$11:$C$410,$A30,BOM!$D$11:$D$410,"<>",BOM!$R$11:$R$410,"NSW Purchased") -> 0 | F30: =IF($B30=0,0,E30/$B30) -> 0 | G30: =COUNTIFS(BOM!$C$11:$C$410,$A30,BOM!$D$11:$D$410,"<>",BOM!$R$11:$R$410,"Received")+COUNTIFS(BOM!$C$11:$C$410,$A30,BOM!$D$11:$D$410,"<>",BOM!$R$11:$R$410,"NSW Purchased") -> 0 | H30: =IF($B30=0,0,G30/$B30) -> 0 | I30: =COUNTIFS(BOM!$C$11:$C$410,$A30,BOM!$AF$11:$AF$410,"OVERDUE") -> 0 | J30: =COUNTIFS(BOM!$C$11:$C$410,$A30,BOM!$AF$11:$AF$410,"?*") -> 0 | K30: =SUMIFS(BOM!$AB$11:$AB$410,BOM!$C$11:$C$410,$A30,BOM!$R$11:$R$410,"<>Cancelled") -> 0
A31: =Lists!$B$6 -> Electrical | B31: =COUNTIFS(BOM!$C$11:$C$410,$A31,BOM!$D$11:$D$410,"<>",BOM!$R$11:$R$410,"<>Cancelled") -> 0 | C31: =COUNTIFS(BOM!$C$11:$C$410,$A31,BOM!$D$11:$D$410,"<>",BOM!$R$11:$R$410,"<>Cancelled")-COUNTIFS(BOM!$C$11:$C$410,$A31,BOM!$D$11:$D$410,"<>",BOM!$R$11:$R$410,"Not Finalized")-COUNTIFS(BOM!$C$11:$C$410,$A31,BOM!$D$11:$D$410,"<>",BOM!$R$11:$R$410,"") -> 0 | D31: =IF($B31=0,0,C31/$B31) -> 0 | E31: =COUNTIFS(BOM!$C$11:$C$410,$A31,BOM!$D$11:$D$410,"<>",BOM!$R$11:$R$410,"Purchased – Not Received")+COUNTIFS(BOM!$C$11:$C$410,$A31,BOM!$D$11:$D$410,"<>",BOM!$R$11:$R$410,"Received")+COUNTIFS(BOM!$C$11:$C$410,$A31,BOM!$D$11:$D$410,"<>",BOM!$R$11:$R$410,"NSW Purchased") -> 0 | F31: =IF($B31=0,0,E31/$B31) -> 0 | G31: =COUNTIFS(BOM!$C$11:$C$410,$A31,BOM!$D$11:$D$410,"<>",BOM!$R$11:$R$410,"Received")+COUNTIFS(BOM!$C$11:$C$410,$A31,BOM!$D$11:$D$410,"<>",BOM!$R$11:$R$410,"NSW Purchased") -> 0 | H31: =IF($B31=0,0,G31/$B31) -> 0 | I31: =COUNTIFS(BOM!$C$11:$C$410,$A31,BOM!$AF$11:$AF$410,"OVERDUE") -> 0 | J31: =COUNTIFS(BOM!$C$11:$C$410,$A31,BOM!$AF$11:$AF$410,"?*") -> 0 | K31: =SUMIFS(BOM!$AB$11:$AB$410,BOM!$C$11:$C$410,$A31,BOM!$R$11:$R$410,"<>Cancelled") -> 0
A32: =Lists!$B$7 -> Pneumatic | B32: =COUNTIFS(BOM!$C$11:$C$410,$A32,BOM!$D$11:$D$410,"<>",BOM!$R$11:$R$410,"<>Cancelled") -> 0 | C32: =COUNTIFS(BOM!$C$11:$C$410,$A32,BOM!$D$11:$D$410,"<>",BOM!$R$11:$R$410,"<>Cancelled")-COUNTIFS(BOM!$C$11:$C$410,$A32,BOM!$D$11:$D$410,"<>",BOM!$R$11:$R$410,"Not Finalized")-COUNTIFS(BOM!$C$11:$C$410,$A32,BOM!$D$11:$D$410,"<>",BOM!$R$11:$R$410,"") -> 0 | D32: =IF($B32=0,0,C32/$B32) -> 0 | E32: =COUNTIFS(BOM!$C$11:$C$410,$A32,BOM!$D$11:$D$410,"<>",BOM!$R$11:$R$410,"Purchased – Not Received")+COUNTIFS(BOM!$C$11:$C$410,$A32,BOM!$D$11:$D$410,"<>",BOM!$R$11:$R$410,"Received")+COUNTIFS(BOM!$C$11:$C$410,$A32,BOM!$D$11:$D$410,"<>",BOM!$R$11:$R$410,"NSW Purchased") -> 0 | F32: =IF($B32=0,0,E32/$B32) -> 0 | G32: =COUNTIFS(BOM!$C$11:$C$410,$A32,BOM!$D$11:$D$410,"<>",BOM!$R$11:$R$410,"Received")+COUNTIFS(BOM!$C$11:$C$410,$A32,BOM!$D$11:$D$410,"<>",BOM!$R$11:$R$410,"NSW Purchased") -> 0 | H32: =IF($B32=0,0,G32/$B32) -> 0 | I32: =COUNTIFS(BOM!$C$11:$C$410,$A32,BOM!$AF$11:$AF$410,"OVERDUE") -> 0 | J32: =COUNTIFS(BOM!$C$11:$C$410,$A32,BOM!$AF$11:$AF$410,"?*") -> 0 | K32: =SUMIFS(BOM!$AB$11:$AB$410,BOM!$C$11:$C$410,$A32,BOM!$R$11:$R$410,"<>Cancelled") -> 0
A33: =Lists!$B$8 -> Software / Vision | B33: =COUNTIFS(BOM!$C$11:$C$410,$A33,BOM!$D$11:$D$410,"<>",BOM!$R$11:$R$410,"<>Cancelled") -> 0 | C33: =COUNTIFS(BOM!$C$11:$C$410,$A33,BOM!$D$11:$D$410,"<>",BOM!$R$11:$R$410,"<>Cancelled")-COUNTIFS(BOM!$C$11:$C$410,$A33,BOM!$D$11:$D$410,"<>",BOM!$R$11:$R$410,"Not Finalized")-COUNTIFS(BOM!$C$11:$C$410,$A33,BOM!$D$11:$D$410,"<>",BOM!$R$11:$R$410,"") -> 0 | D33: =IF($B33=0,0,C33/$B33) -> 0 | E33: =COUNTIFS(BOM!$C$11:$C$410,$A33,BOM!$D$11:$D$410,"<>",BOM!$R$11:$R$410,"Purchased – Not Received")+COUNTIFS(BOM!$C$11:$C$410,$A33,BOM!$D$11:$D$410,"<>",BOM!$R$11:$R$410,"Received")+COUNTIFS(BOM!$C$11:$C$410,$A33,BOM!$D$11:$D$410,"<>",BOM!$R$11:$R$410,"NSW Purchased") -> 0 | F33: =IF($B33=0,0,E33/$B33) -> 0 | G33: =COUNTIFS(BOM!$C$11:$C$410,$A33,BOM!$D$11:$D$410,"<>",BOM!$R$11:$R$410,"Received")+COUNTIFS(BOM!$C$11:$C$410,$A33,BOM!$D$11:$D$410,"<>",BOM!$R$11:$R$410,"NSW Purchased") -> 0 | H33: =IF($B33=0,0,G33/$B33) -> 0 | I33: =COUNTIFS(BOM!$C$11:$C$410,$A33,BOM!$AF$11:$AF$410,"OVERDUE") -> 0 | J33: =COUNTIFS(BOM!$C$11:$C$410,$A33,BOM!$AF$11:$AF$410,"?*") -> 0 | K33: =SUMIFS(BOM!$AB$11:$AB$410,BOM!$C$11:$C$410,$A33,BOM!$R$11:$R$410,"<>Cancelled") -> 0
A34: =Lists!$B$9 -> Others | B34: =COUNTIFS(BOM!$C$11:$C$410,$A34,BOM!$D$11:$D$410,"<>",BOM!$R$11:$R$410,"<>Cancelled") -> 0 | C34: =COUNTIFS(BOM!$C$11:$C$410,$A34,BOM!$D$11:$D$410,"<>",BOM!$R$11:$R$410,"<>Cancelled")-COUNTIFS(BOM!$C$11:$C$410,$A34,BOM!$D$11:$D$410,"<>",BOM!$R$11:$R$410,"Not Finalized")-COUNTIFS(BOM!$C$11:$C$410,$A34,BOM!$D$11:$D$410,"<>",BOM!$R$11:$R$410,"") -> 0 | D34: =IF($B34=0,0,C34/$B34) -> 0 | E34: =COUNTIFS(BOM!$C$11:$C$410,$A34,BOM!$D$11:$D$410,"<>",BOM!$R$11:$R$410,"Purchased – Not Received")+COUNTIFS(BOM!$C$11:$C$410,$A34,BOM!$D$11:$D$410,"<>",BOM!$R$11:$R$410,"Received")+COUNTIFS(BOM!$C$11:$C$410,$A34,BOM!$D$11:$D$410,"<>",BOM!$R$11:$R$410,"NSW Purchased") -> 0 | F34: =IF($B34=0,0,E34/$B34) -> 0 | G34: =COUNTIFS(BOM!$C$11:$C$410,$A34,BOM!$D$11:$D$410,"<>",BOM!$R$11:$R$410,"Received")+COUNTIFS(BOM!$C$11:$C$410,$A34,BOM!$D$11:$D$410,"<>",BOM!$R$11:$R$410,"NSW Purchased") -> 0 | H34: =IF($B34=0,0,G34/$B34) -> 0 | I34: =COUNTIFS(BOM!$C$11:$C$410,$A34,BOM!$AF$11:$AF$410,"OVERDUE") -> 0 | J34: =COUNTIFS(BOM!$C$11:$C$410,$A34,BOM!$AF$11:$AF$410,"?*") -> 0 | K34: =SUMIFS(BOM!$AB$11:$AB$410,BOM!$C$11:$C$410,$A34,BOM!$R$11:$R$410,"<>Cancelled") -> 0
A35: TOTAL | B35: =SUM(B30:B34) -> 0 | C35: =SUM(C30:C34) -> 0 | D35: =IF($B35=0,0,C35/$B35) -> 0 | E35: =SUM(E30:E34) -> 0 | F35: =IF($B35=0,0,E35/$B35) -> 0 | G35: =SUM(G30:G34) -> 0 | H35: =IF($B35=0,0,G35/$B35) -> 0 | I35: =SUM(I30:I34) -> 0 | J35: =SUM(J30:J34) -> 0 | K35: =SUM(K30:K34) -> 0
A37: By Category
A38: Group | B38: Lines | C38: Finalized | D38: % Final | E38: Ordered | F38: % Ordered | G38: Received | H38: % Rcvd | I38: Overdue | J38: Flags (any) | K38: Value (RM)
A39: =Lists!$C$5 -> Fabricated Part | B39: =COUNTIFS(BOM!$G$11:$G$410,$A39,BOM!$D$11:$D$410,"<>",BOM!$R$11:$R$410,"<>Cancelled") -> 0 | C39: =COUNTIFS(BOM!$G$11:$G$410,$A39,BOM!$D$11:$D$410,"<>",BOM!$R$11:$R$410,"<>Cancelled")-COUNTIFS(BOM!$G$11:$G$410,$A39,BOM!$D$11:$D$410,"<>",BOM!$R$11:$R$410,"Not Finalized")-COUNTIFS(BOM!$G$11:$G$410,$A39,BOM!$D$11:$D$410,"<>",BOM!$R$11:$R$410,"") -> 0 | D39: =IF($B39=0,0,C39/$B39) -> 0 | E39: =COUNTIFS(BOM!$G$11:$G$410,$A39,BOM!$D$11:$D$410,"<>",BOM!$R$11:$R$410,"Purchased – Not Received")+COUNTIFS(BOM!$G$11:$G$410,$A39,BOM!$D$11:$D$410,"<>",BOM!$R$11:$R$410,"Received")+COUNTIFS(BOM!$G$11:$G$410,$A39,BOM!$D$11:$D$410,"<>",BOM!$R$11:$R$410,"NSW Purchased") -> 0 | F39: =IF($B39=0,0,E39/$B39) -> 0 | G39: =COUNTIFS(BOM!$G$11:$G$410,$A39,BOM!$D$11:$D$410,"<>",BOM!$R$11:$R$410,"Received")+COUNTIFS(BOM!$G$11:$G$410,$A39,BOM!$D$11:$D$410,"<>",BOM!$R$11:$R$410,"NSW Purchased") -> 0 | H39: =IF($B39=0,0,G39/$B39) -> 0 | I39: =COUNTIFS(BOM!$G$11:$G$410,$A39,BOM!$AF$11:$AF$410,"OVERDUE") -> 0 | J39: =COUNTIFS(BOM!$G$11:$G$410,$A39,BOM!$AF$11:$AF$410,"?*") -> 0 | K39: =SUMIFS(BOM!$AB$11:$AB$410,BOM!$G$11:$G$410,$A39,BOM!$R$11:$R$410,"<>Cancelled") -> 0
A40: =Lists!$C$6 -> Std Mechanical | B40: =COUNTIFS(BOM!$G$11:$G$410,$A40,BOM!$D$11:$D$410,"<>",BOM!$R$11:$R$410,"<>Cancelled") -> 0 | C40: =COUNTIFS(BOM!$G$11:$G$410,$A40,BOM!$D$11:$D$410,"<>",BOM!$R$11:$R$410,"<>Cancelled")-COUNTIFS(BOM!$G$11:$G$410,$A40,BOM!$D$11:$D$410,"<>",BOM!$R$11:$R$410,"Not Finalized")-COUNTIFS(BOM!$G$11:$G$410,$A40,BOM!$D$11:$D$410,"<>",BOM!$R$11:$R$410,"") -> 0 | D40: =IF($B40=0,0,C40/$B40) -> 0 | E40: =COUNTIFS(BOM!$G$11:$G$410,$A40,BOM!$D$11:$D$410,"<>",BOM!$R$11:$R$410,"Purchased – Not Received")+COUNTIFS(BOM!$G$11:$G$410,$A40,BOM!$D$11:$D$410,"<>",BOM!$R$11:$R$410,"Received")+COUNTIFS(BOM!$G$11:$G$410,$A40,BOM!$D$11:$D$410,"<>",BOM!$R$11:$R$410,"NSW Purchased") -> 0 | F40: =IF($B40=0,0,E40/$B40) -> 0 | G40: =COUNTIFS(BOM!$G$11:$G$410,$A40,BOM!$D$11:$D$410,"<>",BOM!$R$11:$R$410,"Received")+COUNTIFS(BOM!$G$11:$G$410,$A40,BOM!$D$11:$D$410,"<>",BOM!$R$11:$R$410,"NSW Purchased") -> 0 | H40: =IF($B40=0,0,G40/$B40) -> 0 | I40: =COUNTIFS(BOM!$G$11:$G$410,$A40,BOM!$AF$11:$AF$410,"OVERDUE") -> 0 | J40: =COUNTIFS(BOM!$G$11:$G$410,$A40,BOM!$AF$11:$AF$410,"?*") -> 0 | K40: =SUMIFS(BOM!$AB$11:$AB$410,BOM!$G$11:$G$410,$A40,BOM!$R$11:$R$410,"<>Cancelled") -> 0
A41: =Lists!$C$7 -> Pneumatic | B41: =COUNTIFS(BOM!$G$11:$G$410,$A41,BOM!$D$11:$D$410,"<>",BOM!$R$11:$R$410,"<>Cancelled") -> 0 | C41: =COUNTIFS(BOM!$G$11:$G$410,$A41,BOM!$D$11:$D$410,"<>",BOM!$R$11:$R$410,"<>Cancelled")-COUNTIFS(BOM!$G$11:$G$410,$A41,BOM!$D$11:$D$410,"<>",BOM!$R$11:$R$410,"Not Finalized")-COUNTIFS(BOM!$G$11:$G$410,$A41,BOM!$D$11:$D$410,"<>",BOM!$R$11:$R$410,"") -> 0 | D41: =IF($B41=0,0,C41/$B41) -> 0 | E41: =COUNTIFS(BOM!$G$11:$G$410,$A41,BOM!$D$11:$D$410,"<>",BOM!$R$11:$R$410,"Purchased – Not Received")+COUNTIFS(BOM!$G$11:$G$410,$A41,BOM!$D$11:$D$410,"<>",BOM!$R$11:$R$410,"Received")+COUNTIFS(BOM!$G$11:$G$410,$A41,BOM!$D$11:$D$410,"<>",BOM!$R$11:$R$410,"NSW Purchased") -> 0 | F41: =IF($B41=0,0,E41/$B41) -> 0 | G41: =COUNTIFS(BOM!$G$11:$G$410,$A41,BOM!$D$11:$D$410,"<>",BOM!$R$11:$R$410,"Received")+COUNTIFS(BOM!$G$11:$G$410,$A41,BOM!$D$11:$D$410,"<>",BOM!$R$11:$R$410,"NSW Purchased") -> 0 | H41: =IF($B41=0,0,G41/$B41) -> 0 | I41: =COUNTIFS(BOM!$G$11:$G$410,$A41,BOM!$AF$11:$AF$410,"OVERDUE") -> 0 | J41: =COUNTIFS(BOM!$G$11:$G$410,$A41,BOM!$AF$11:$AF$410,"?*") -> 0 | K41: =SUMIFS(BOM!$AB$11:$AB$410,BOM!$G$11:$G$410,$A41,BOM!$R$11:$R$410,"<>Cancelled") -> 0
A42: =Lists!$C$8 -> Vacuum | B42: =COUNTIFS(BOM!$G$11:$G$410,$A42,BOM!$D$11:$D$410,"<>",BOM!$R$11:$R$410,"<>Cancelled") -> 0 | C42: =COUNTIFS(BOM!$G$11:$G$410,$A42,BOM!$D$11:$D$410,"<>",BOM!$R$11:$R$410,"<>Cancelled")-COUNTIFS(BOM!$G$11:$G$410,$A42,BOM!$D$11:$D$410,"<>",BOM!$R$11:$R$410,"Not Finalized")-COUNTIFS(BOM!$G$11:$G$410,$A42,BOM!$D$11:$D$410,"<>",BOM!$R$11:$R$410,"") -> 0 | D42: =IF($B42=0,0,C42/$B42) -> 0 | E42: =COUNTIFS(BOM!$G$11:$G$410,$A42,BOM!$D$11:$D$410,"<>",BOM!$R$11:$R$410,"Purchased – Not Received")+COUNTIFS(BOM!$G$11:$G$410,$A42,BOM!$D$11:$D$410,"<>",BOM!$R$11:$R$410,"Received")+COUNTIFS(BOM!$G$11:$G$410,$A42,BOM!$D$11:$D$410,"<>",BOM!$R$11:$R$410,"NSW Purchased") -> 0 | F42: =IF($B42=0,0,E42/$B42) -> 0 | G42: =COUNTIFS(BOM!$G$11:$G$410,$A42,BOM!$D$11:$D$410,"<>",BOM!$R$11:$R$410,"Received")+COUNTIFS(BOM!$G$11:$G$410,$A42,BOM!$D$11:$D$410,"<>",BOM!$R$11:$R$410,"NSW Purchased") -> 0 | H42: =IF($B42=0,0,G42/$B42) -> 0 | I42: =COUNTIFS(BOM!$G$11:$G$410,$A42,BOM!$AF$11:$AF$410,"OVERDUE") -> 0 | J42: =COUNTIFS(BOM!$G$11:$G$410,$A42,BOM!$AF$11:$AF$410,"?*") -> 0 | K42: =SUMIFS(BOM!$AB$11:$AB$410,BOM!$G$11:$G$410,$A42,BOM!$R$11:$R$410,"<>Cancelled") -> 0
A43: =Lists!$C$9 -> Motion / Actuator | B43: =COUNTIFS(BOM!$G$11:$G$410,$A43,BOM!$D$11:$D$410,"<>",BOM!$R$11:$R$410,"<>Cancelled") -> 0 | C43: =COUNTIFS(BOM!$G$11:$G$410,$A43,BOM!$D$11:$D$410,"<>",BOM!$R$11:$R$410,"<>Cancelled")-COUNTIFS(BOM!$G$11:$G$410,$A43,BOM!$D$11:$D$410,"<>",BOM!$R$11:$R$410,"Not Finalized")-COUNTIFS(BOM!$G$11:$G$410,$A43,BOM!$D$11:$D$410,"<>",BOM!$R$11:$R$410,"") -> 0 | D43: =IF($B43=0,0,C43/$B43) -> 0 | E43: =COUNTIFS(BOM!$G$11:$G$410,$A43,BOM!$D$11:$D$410,"<>",BOM!$R$11:$R$410,"Purchased – Not Received")+COUNTIFS(BOM!$G$11:$G$410,$A43,BOM!$D$11:$D$410,"<>",BOM!$R$11:$R$410,"Received")+COUNTIFS(BOM!$G$11:$G$410,$A43,BOM!$D$11:$D$410,"<>",BOM!$R$11:$R$410,"NSW Purchased") -> 0 | F43: =IF($B43=0,0,E43/$B43) -> 0 | G43: =COUNTIFS(BOM!$G$11:$G$410,$A43,BOM!$D$11:$D$410,"<>",BOM!$R$11:$R$410,"Received")+COUNTIFS(BOM!$G$11:$G$410,$A43,BOM!$D$11:$D$410,"<>",BOM!$R$11:$R$410,"NSW Purchased") -> 0 | H43: =IF($B43=0,0,G43/$B43) -> 0 | I43: =COUNTIFS(BOM!$G$11:$G$410,$A43,BOM!$AF$11:$AF$410,"OVERDUE") -> 0 | J43: =COUNTIFS(BOM!$G$11:$G$410,$A43,BOM!$AF$11:$AF$410,"?*") -> 0 | K43: =SUMIFS(BOM!$AB$11:$AB$410,BOM!$G$11:$G$410,$A43,BOM!$R$11:$R$410,"<>Cancelled") -> 0
A44: =Lists!$C$10 -> Electrical / Control | B44: =COUNTIFS(BOM!$G$11:$G$410,$A44,BOM!$D$11:$D$410,"<>",BOM!$R$11:$R$410,"<>Cancelled") -> 0 | C44: =COUNTIFS(BOM!$G$11:$G$410,$A44,BOM!$D$11:$D$410,"<>",BOM!$R$11:$R$410,"<>Cancelled")-COUNTIFS(BOM!$G$11:$G$410,$A44,BOM!$D$11:$D$410,"<>",BOM!$R$11:$R$410,"Not Finalized")-COUNTIFS(BOM!$G$11:$G$410,$A44,BOM!$D$11:$D$410,"<>",BOM!$R$11:$R$410,"") -> 0 | D44: =IF($B44=0,0,C44/$B44) -> 0 | E44: =COUNTIFS(BOM!$G$11:$G$410,$A44,BOM!$D$11:$D$410,"<>",BOM!$R$11:$R$410,"Purchased – Not Received")+COUNTIFS(BOM!$G$11:$G$410,$A44,BOM!$D$11:$D$410,"<>",BOM!$R$11:$R$410,"Received")+COUNTIFS(BOM!$G$11:$G$410,$A44,BOM!$D$11:$D$410,"<>",BOM!$R$11:$R$410,"NSW Purchased") -> 0 | F44: =IF($B44=0,0,E44/$B44) -> 0 | G44: =COUNTIFS(BOM!$G$11:$G$410,$A44,BOM!$D$11:$D$410,"<>",BOM!$R$11:$R$410,"Received")+COUNTIFS(BOM!$G$11:$G$410,$A44,BOM!$D$11:$D$410,"<>",BOM!$R$11:$R$410,"NSW Purchased") -> 0 | H44: =IF($B44=0,0,G44/$B44) -> 0 | I44: =COUNTIFS(BOM!$G$11:$G$410,$A44,BOM!$AF$11:$AF$410,"OVERDUE") -> 0 | J44: =COUNTIFS(BOM!$G$11:$G$410,$A44,BOM!$AF$11:$AF$410,"?*") -> 0 | K44: =SUMIFS(BOM!$AB$11:$AB$410,BOM!$G$11:$G$410,$A44,BOM!$R$11:$R$410,"<>Cancelled") -> 0
...

Sheet Customer View
A1: Bill of Materials
A2: Auto from BOM — no supplier, PR/PO, price or internal remarks. Copy → Paste Values into a new file before sending to Teleflex.
A4: Item | B4: Sub-Assembly | C4: Discipline | D4: Description | E4: Manufacturer Part No. | F4: Manufacturer | G4: Total Qty | H4: Unit | I4: Drawing No. / Rev | J4: Status | K4: ETA
A5: =IF(OR(BOM!$D11="",BOM!$R11="Cancelled"),"",IF(BOM!A11="","",BOM!A11)) | B5: =IF(OR(BOM!$D11="",BOM!$R11="Cancelled"),"",IF(BOM!B11="","",BOM!B11)) | C5: =IF(OR(BOM!$D11="",BOM!$R11="Cancelled"),"",IF(BOM!C11="","",BOM!C11)) | D5: =IF(OR(BOM!$D11="",BOM!$R11="Cancelled"),"",IF(BOM!D11="","",BOM!D11)) | E5: =IF(OR(BOM!$D11="",BOM!$R11="Cancelled"),"",IF(BOM!E11="","",BOM!E11)) | F5: =IF(OR(BOM!$D11="",BOM!$R11="Cancelled"),"",IF(BOM!F11="","",BOM!F11)) | G5: =IF(OR(BOM!$D11="",BOM!$R11="Cancelled"),"",IF(BOM!J11="","",BOM!J11)) | H5: =IF(OR(BOM!$D11="",BOM!$R11="Cancelled"),"",IF(BOM!K11="","",BOM!K11)) | I5: =IF(OR(BOM!$D11="",BOM!$R11="Cancelled"),"",IF(BOM!M11="","",BOM!M11)) | J5: =IF(OR(BOM!$D11="",BOM!$R11="Cancelled"),"",IF(OR(BOM!R11="Received",BOM!R11="NSW Purchased"),"Received",IF(BOM!R11="Purchased – Not Received","Ordered",IF(BOM!R11="Finalized – Not Purchased","Design Released","In Design")))) | K5: =IF(OR(BOM!$D11="",BOM!$R11="Cancelled"),"",IF(BOM!W11="","",BOM!W11))
A6: =IF(OR(BOM!$D12="",BOM!$R12="Cancelled"),"",IF(BOM!A12="","",BOM!A12)) | B6: =IF(OR(BOM!$D12="",BOM!$R12="Cancelled"),"",IF(BOM!B12="","",BOM!B12)) | C6: =IF(OR(BOM!$D12="",BOM!$R12="Cancelled"),"",IF(BOM!C12="","",BOM!C12)) | D6: =IF(OR(BOM!$D12="",BOM!$R12="Cancelled"),"",IF(BOM!D12="","",BOM!D12)) | E6: =IF(OR(BOM!$D12="",BOM!$R12="Cancelled"),"",IF(BOM!E12="","",BOM!E12)) | F6: =IF(OR(BOM!$D12="",BOM!$R12="Cancelled"),"",IF(BOM!F12="","",BOM!F12)) | G6: =IF(OR(BOM!$D12="",BOM!$R12="Cancelled"),"",IF(BOM!J12="","",BOM!J12)) | H6: =IF(OR(BOM!$D12="",BOM!$R12="Cancelled"),"",IF(BOM!K12="","",BOM!K12)) | I6: =IF(OR(BOM!$D12="",BOM!$R12="Cancelled"),"",IF(BOM!M12="","",BOM!M12)) | J6: =IF(OR(BOM!$D12="",BOM!$R12="Cancelled"),"",IF(OR(BOM!R12="Received",BOM!R12="NSW Purchased"),"Received",IF(BOM!R12="Purchased – Not Received","Ordered",IF(BOM!R12="Finalized – Not Purchased","Design Released","In Design")))) | K6: =IF(OR(BOM!$D12="",BOM!$R12="Cancelled"),"",IF(BOM!W12="","",BOM!W12))
A7: =IF(OR(BOM!$D13="",BOM!$R13="Cancelled"),"",IF(BOM!A13="","",BOM!A13)) | B7: =IF(OR(BOM!$D13="",BOM!$R13="Cancelled"),"",IF(BOM!B13="","",BOM!B13)) | C7: =IF(OR(BOM!$D13="",BOM!$R13="Cancelled"),"",IF(BOM!C13="","",BOM!C13)) | D7: =IF(OR(BOM!$D13="",BOM!$R13="Cancelled"),"",IF(BOM!D13="","",BOM!D13)) | E7: =IF(OR(BOM!$D13="",BOM!$R13="Cancelled"),"",IF(BOM!E13="","",BOM!E13)) | F7: =IF(OR(BOM!$D13="",BOM!$R13="Cancelled"),"",IF(BOM!F13="","",BOM!F13)) | G7: =IF(OR(BOM!$D13="",BOM!$R13="Cancelled"),"",IF(BOM!J13="","",BOM!J13)) | H7: =IF(OR(BOM!$D13="",BOM!$R13="Cancelled"),"",IF(BOM!K13="","",BOM!K13)) | I7: =IF(OR(BOM!$D13="",BOM!$R13="Cancelled"),"",IF(BOM!M13="","",BOM!M13)) | J7: =IF(OR(BOM!$D13="",BOM!$R13="Cancelled"),"",IF(OR(BOM!R13="Received",BOM!R13="NSW Purchased"),"Received",IF(BOM!R13="Purchased – Not Received","Ordered",IF(BOM!R13="Finalized – Not Purchased","Design Released","In Design")))) | K7: =IF(OR(BOM!$D13="",BOM!$R13="Cancelled"),"",IF(BOM!W13="","",BOM!W13))
A8: =IF(OR(BOM!$D14="",BOM!$R14="Cancelled"),"",IF(BOM!A14="","",BOM!A14)) | B8: =IF(OR(BOM!$D14="",BOM!$R14="Cancelled"),"",IF(BOM!B14="","",BOM!B14)) | C8: =IF(OR(BOM!$D14="",BOM!$R14="Cancelled"),"",IF(BOM!C14="","",BOM!C14)) | D8: =IF(OR(BOM!$D14="",BOM!$R14="Cancelled"),"",IF(BOM!D14="","",BOM!D14)) | E8: =IF(OR(BOM!$D14="",BOM!$R14="Cancelled"),"",IF(BOM!E14="","",BOM!E14)) | F8: =IF(OR(BOM!$D14="",BOM!$R14="Cancelled"),"",IF(BOM!F14="","",BOM!F14)) | G8: =IF(OR(BOM!$D14="",BOM!$R14="Cancelled"),"",IF(BOM!J14="","",BOM!J14)) | H8: =IF(OR(BOM!$D14="",BOM!$R14="Cancelled"),"",IF(BOM!K14="","",BOM!K14)) | I8: =IF(OR(BOM!$D14="",BOM!$R14="Cancelled"),"",IF(BOM!M14="","",BOM!M14)) | J8: =IF(OR(BOM!$D14="",BOM!$R14="Cancelled"),"",IF(OR(BOM!R14="Received",BOM!R14="NSW Purchased"),"Received",IF(BOM!R14="Purchased – Not Received","Ordered",IF(BOM!R14="Finalized – Not Purchased","Design Released","In Design")))) | K8: =IF(OR(BOM!$D14="",BOM!$R14="Cancelled"),"",IF(BOM!W14="","",BOM!W14))
A9: =IF(OR(BOM!$D15="",BOM!$R15="Cancelled"),"",IF(BOM!A15="","",BOM!A15)) | B9: =IF(OR(BOM!$D15="",BOM!$R15="Cancelled"),"",IF(BOM!B15="","",BOM!B15)) | C9: =IF(OR(BOM!$D15="",BOM!$R15="Cancelled"),"",IF(BOM!C15="","",BOM!C15)) | D9: =IF(OR(BOM!$D15="",BOM!$R15="Cancelled"),"",IF(BOM!D15="","",BOM!D15)) | E9: =IF(OR(BOM!$D15="",BOM!$R15="Cancelled"),"",IF(BOM!E15="","",BOM!E15)) | F9: =IF(OR(BOM!$D15="",BOM!$R15="Cancelled"),"",IF(BOM!F15="","",BOM!F15)) | G9: =IF(OR(BOM!$D15="",BOM!$R15="Cancelled"),"",IF(BOM!J15="","",BOM!J15)) | H9: =IF(OR(BOM!$D15="",BOM!$R15="Cancelled"),"",IF(BOM!K15="","",BOM!K15)) | I9: =IF(OR(BOM!$D15="",BOM!$R15="Cancelled"),"",IF(BOM!M15="","",BOM!M15)) | J9: =IF(OR(BOM!$D15="",BOM!$R15="Cancelled"),"",IF(OR(BOM!R15="Received",BOM!R15="NSW Purchased"),"Received",IF(BOM!R15="Purchased – Not Received","Ordered",IF(BOM!R15="Finalized – Not Purchased","Design Released","In Design")))) | K9: =IF(OR(BOM!$D15="",BOM!$R15="Cancelled"),"",IF(BOM!W15="","",BOM!W15))
A10: =IF(OR(BOM!$D16="",BOM!$R16="Cancelled"),"",IF(BOM!A16="","",BOM!A16)) | B10: =IF(OR(BOM!$D16="",BOM!$R16="Cancelled"),"",IF(BOM!B16="","",BOM!B16)) | C10: =IF(OR(BOM!$D16="",BOM!$R16="Cancelled"),"",IF(BOM!C16="","",BOM!C16)) | D10: =IF(OR(BOM!$D16="",BOM!$R16="Cancelled"),"",IF(BOM!D16="","",BOM!D16)) | E10: =IF(OR(BOM!$D16="",BOM!$R16="Cancelled"),"",IF(BOM!E16="","",BOM!E16)) | F10: =IF(OR(BOM!$D16="",BOM!$R16="Cancelled"),"",IF(BOM!F16="","",BOM!F16)) | G10: =IF(OR(BOM!$D16="",BOM!$R16="Cancelled"),"",IF(BOM!J16="","",BOM!J16)) | H10: =IF(OR(BOM!$D16="",BOM!$R16="Cancelled"),"",IF(BOM!K16="","",BOM!K16)) | I10: =IF(OR(BOM!$D16="",BOM!$R16="Cancelled"),"",IF(BOM!M16="","",BOM!M16)) | J10: =IF(OR(BOM!$D16="",BOM!$R16="Cancelled"),"",IF(OR(BOM!R16="Received",BOM!R16="NSW Purchased"),"Received",IF(BOM!R16="Purchased – Not Received","Ordered",IF(BOM!R16="Finalized – Not Purchased","Design Released","In Design")))) | K10: =IF(OR(BOM!$D16="",BOM!$R16="Cancelled"),"",IF(BOM!W16="","",BOM!W16))
A11: =IF(OR(BOM!$D17="",BOM!$R17="Cancelled"),"",IF(BOM!A17="","",BOM!A17)) | B11: =IF(OR(BOM!$D17="",BOM!$R17="Cancelled"),"",IF(BOM!B17="","",BOM!B17)) | C11: =IF(OR(BOM!$D17="",BOM!$R17="Cancelled"),"",IF(BOM!C17="","",BOM!C17)) | D11: =IF(OR(BOM!$D17="",BOM!$R17="Cancelled"),"",IF(BOM!D17="","",BOM!D17)) | E11: =IF(OR(BOM!$D17="",BOM!$R17="Cancelled"),"",IF(BOM!E17="","",BOM!E17)) | F11: =IF(OR(BOM!$D17="",BOM!$R17="Cancelled"),"",IF(BOM!F17="","",BOM!F17)) | G11: =IF(OR(BOM!$D17="",BOM!$R17="Cancelled"),"",IF(BOM!J17="","",BOM!J17)) | H11: =IF(OR(BOM!$D17="",BOM!$R17="Cancelled"),"",IF(BOM!K17="","",BOM!K17)) | I11: =IF(OR(BOM!$D17="",BOM!$R17="Cancelled"),"",IF(BOM!M17="","",BOM!M17)) | J11: =IF(OR(BOM!$D17="",BOM!$R17="Cancelled"),"",IF(OR(BOM!R17="Received",BOM!R17="NSW Purchased"),"Received",IF(BOM!R17="Purchased – Not Received","Ordered",IF(BOM!R17="Finalized – Not Purchased","Design Released","In Design")))) | K11: =IF(OR(BOM!$D17="",BOM!$R17="Cancelled"),"",IF(BOM!W17="","",BOM!W17))
A12: =IF(OR(BOM!$D18="",BOM!$R18="Cancelled"),"",IF(BOM!A18="","",BOM!A18)) | B12: =IF(OR(BOM!$D18="",BOM!$R18="Cancelled"),"",IF(BOM!B18="","",BOM!B18)) | C12: =IF(OR(BOM!$D18="",BOM!$R18="Cancelled"),"",IF(BOM!C18="","",BOM!C18)) | D12: =IF(OR(BOM!$D18="",BOM!$R18="Cancelled"),"",IF(BOM!D18="","",BOM!D18)) | E12: =IF(OR(BOM!$D18="",BOM!$R18="Cancelled"),"",IF(BOM!E18="","",BOM!E18)) | F12: =IF(OR(BOM!$D18="",BOM!$R18="Cancelled"),"",IF(BOM!F18="","",BOM!F18)) | G12: =IF(OR(BOM!$D18="",BOM!$R18="Cancelled"),"",IF(BOM!J18="","",BOM!J18)) | H12: =IF(OR(BOM!$D18="",BOM!$R18="Cancelled"),"",IF(BOM!K18="","",BOM!K18)) | I12: =IF(OR(BOM!$D18="",BOM!$R18="Cancelled"),"",IF(BOM!M18="","",BOM!M18)) | J12: =IF(OR(BOM!$D18="",BOM!$R18="Cancelled"),"",IF(OR(BOM!R18="Received",BOM!R18="NSW Purchased"),"Received",IF(BOM!R18="Purchased – Not Received","Ordered",IF(BOM!R18="Finalized – Not Purchased","Design Released","In Design")))) | K12: =IF(OR(BOM!$D18="",BOM!$R18="Cancelled"),"",IF(BOM!W18="","",BOM!W18))
A13: =IF(OR(BOM!$D19="",BOM!$R19="Cancelled"),"",IF(BOM!A19="","",BOM!A19)) | B13: =IF(OR(BOM!$D19="",BOM!$R19="Cancelled"),"",IF(BOM!B19="","",BOM!B19)) | C13: =IF(OR(BOM!$D19="",BOM!$R19="Cancelled"),"",IF(BOM!C19="","",BOM!C19)) | D13: =IF(OR(BOM!$D19="",BOM!$R19="Cancelled"),"",IF(BOM!D19="","",BOM!D19)) | E13: =IF(OR(BOM!$D19="",BOM!$R19="Cancelled"),"",IF(BOM!E19="","",BOM!E19)) | F13: =IF(OR(BOM!$D19="",BOM!$R19="Cancelled"),"",IF(BOM!F19="","",BOM!F19)) | G13: =IF(OR(BOM!$D19="",BOM!$R19="Cancelled"),"",IF(BOM!J19="","",BOM!J19)) | H13: =IF(OR(BOM!$D19="",BOM!$R19="Cancelled"),"",IF(BOM!K19="","",BOM!K19)) | I13: =IF(OR(BOM!$D19="",BOM!$R19="Cancelled"),"",IF(BOM!M19="","",BOM!M19)) | J13: =IF(OR(BOM!$D19="",BOM!$R19="Cancelled"),"",IF(OR(BOM!R19="Received",BOM!R19="NSW Purchased"),"Received",IF(BOM!R19="Purchased – Not Received","Ordered",IF(BOM!R19="Finalized – Not Purchased","Design Released","In Design")))) | K13: =IF(OR(BOM!$D19="",BOM!$R19="Cancelled"),"",IF(BOM!W19="","",BOM!W19))
A14: =IF(OR(BOM!$D20="",BOM!$R20="Cancelled"),"",IF(BOM!A20="","",BOM!A20)) | B14: =IF(OR(BOM!$D20="",BOM!$R20="Cancelled"),"",IF(BOM!B20="","",BOM!B20)) | C14: =IF(OR(BOM!$D20="",BOM!$R20="Cancelled"),"",IF(BOM!C20="","",BOM!C20)) | D14: =IF(OR(BOM!$D20="",BOM!$R20="Cancelled"),"",IF(BOM!D20="","",BOM!D20)) | E14: =IF(OR(BOM!$D20="",BOM!$R20="Cancelled"),"",IF(BOM!E20="","",BOM!E20)) | F14: =IF(OR(BOM!$D20="",BOM!$R20="Cancelled"),"",IF(BOM!F20="","",BOM!F20)) | G14: =IF(OR(BOM!$D20="",BOM!$R20="Cancelled"),"",IF(BOM!J20="","",BOM!J20)) | H14: =IF(OR(BOM!$D20="",BOM!$R20="Cancelled"),"",IF(BOM!K20="","",BOM!K20)) | I14: =IF(OR(BOM!$D20="",BOM!$R20="Cancelled"),"",IF(BOM!M20="","",BOM!M20)) | J14: =IF(OR(BOM!$D20="",BOM!$R20="Cancelled"),"",IF(OR(BOM!R20="Received",BOM!R20="NSW Purchased"),"Received",IF(BOM!R20="Purchased – Not Received","Ordered",IF(BOM!R20="Finalized – Not Purchased","Design Released","In Design")))) | K14: =IF(OR(BOM!$D20="",BOM!$R20="Cancelled"),"",IF(BOM!W20="","",BOM!W20))
A15: =IF(OR(BOM!$D21="",BOM!$R21="Cancelled"),"",IF(BOM!A21="","",BOM!A21)) | B15: =IF(OR(BOM!$D21="",BOM!$R21="Cancelled"),"",IF(BOM!B21="","",BOM!B21)) | C15: =IF(OR(BOM!$D21="",BOM!$R21="Cancelled"),"",IF(BOM!C21="","",BOM!C21)) | D15: =IF(OR(BOM!$D21="",BOM!$R21="Cancelled"),"",IF(BOM!D21="","",BOM!D21)) | E15: =IF(OR(BOM!$D21="",BOM!$R21="Cancelled"),"",IF(BOM!E21="","",BOM!E21)) | F15: =IF(OR(BOM!$D21="",BOM!$R21="Cancelled"),"",IF(BOM!F21="","",BOM!F21)) | G15: =IF(OR(BOM!$D21="",BOM!$R21="Cancelled"),"",IF(BOM!J21="","",BOM!J21)) | H15: =IF(OR(BOM!$D21="",BOM!$R21="Cancelled"),"",IF(BOM!K21="","",BOM!K21)) | I15: =IF(OR(BOM!$D21="",BOM!$R21="Cancelled"),"",IF(BOM!M21="","",BOM!M21)) | J15: =IF(OR(BOM!$D21="",BOM!$R21="Cancelled"),"",IF(OR(BOM!R21="Received",BOM!R21="NSW Purchased"),"Received",IF(BOM!R21="Purchased – Not Received","Ordered",IF(BOM!R21="Finalized – Not Purchased","Design Released","In Design")))) | K15: =IF(OR(BOM!$D21="",BOM!$R21="Cancelled"),"",IF(BOM!W21="","",BOM!W21))
A16: =IF(OR(BOM!$D22="",BOM!$R22="Cancelled"),"",IF(BOM!A22="","",BOM!A22)) | B16: =IF(OR(BOM!$D22="",BOM!$R22="Cancelled"),"",IF(BOM!B22="","",BOM!B22)) | C16: =IF(OR(BOM!$D22="",BOM!$R22="Cancelled"),"",IF(BOM!C22="","",BOM!C22)) | D16: =IF(OR(BOM!$D22="",BOM!$R22="Cancelled"),"",IF(BOM!D22="","",BOM!D22)) | E16: =IF(OR(BOM!$D22="",BOM!$R22="Cancelled"),"",IF(BOM!E22="","",BOM!E22)) | F16: =IF(OR(BOM!$D22="",BOM!$R22="Cancelled"),"",IF(BOM!F22="","",BOM!F22)) | G16: =IF(OR(BOM!$D22="",BOM!$R22="Cancelled"),"",IF(BOM!J22="","",BOM!J22)) | H16: =IF(OR(BOM!$D22="",BOM!$R22="Cancelled"),"",IF(BOM!K22="","",BOM!K22)) | I16: =IF(OR(BOM!$D22="",BOM!$R22="Cancelled"),"",IF(BOM!M22="","",BOM!M22)) | J16: =IF(OR(BOM!$D22="",BOM!$R22="Cancelled"),"",IF(OR(BOM!R22="Received",BOM!R22="NSW Purchased"),"Received",IF(BOM!R22="Purchased – Not Received","Ordered",IF(BOM!R22="Finalized – Not Purchased","Design Released","In Design")))) | K16: =IF(OR(BOM!$D22="",BOM!$R22="Cancelled"),"",IF(BOM!W22="","",BOM!W22))
... A404: =IF(OR(BOM!$D410="",BOM!$R410="Cancelled"),"",IF(BOM!A410="","",BOM!A410)) | B404: =IF(OR(BOM!$D410="",BOM!$R410="Cancelled"),"",IF(BOM!B410="","",BOM!B410)) | C404: =IF(OR(BOM!$D410="",BOM!$R410="Cancelled"),"",IF(BOM!C410="","",BOM!C410)) | D404: =IF(OR(BOM!$D410="",BOM!$R410="Cancelled"),"",IF(BOM!D410="","",BOM!D410)) | E404: =IF(OR(BOM!$D410="",BOM!$R410="Cancelled"),"",IF(BOM!E410="","",BOM!E410)) | F404: =IF(OR(BOM!$D410="",BOM!$R410="Cancelled"),"",IF(BOM!F410="","",BOM!F410)) | G404: =IF(OR(BOM!$D410="",BOM!$R410="Cancelled"),"",IF(BOM!J410="","",BOM!J410)) | H404: =IF(OR(BOM!$D410="",BOM!$R410="Cancelled"),"",IF(BOM!K410="","",BOM!K410)) | I404: =IF(OR(BOM!$D410="",BOM!$R410="Cancelled"),"",IF(BOM!M410="","",BOM!M410)) | J404: =IF(OR(BOM!$D410="",BOM!$R410="Cancelled"),"",IF(OR(BOM!R410="Received",BOM!R410="NSW Purchased"),"Received",IF(BOM!R410="Purchased – Not Received","Ordered",IF(BOM!R410="Finalized – Not Purchased","Design Released","In Design")))) | K404: =IF(OR(BOM!$D410="",BOM!$R410="Cancelled"),"",IF(BOM!W410="","",BOM!W410))

Sheet Revision Log
A1: Revision Log
A2: Add a line every time the BOM is re-issued to Teleflex.
A4: Rev | B4: Date | C4: Changes | D4: By | E4: Approved

Sheet Lists
A1: Dropdown Lists
A2: Yellow = edit per project. Format: <3-digit no.> <NAME>, e.g. 120 SINGULATOR. Add rows at the bottom of the list if needed (up to 15).
A4: Sub-Assembly | B4: Discipline | C4: Category | D4: Status | E4: Make/Buy | F4: Unit
A5: 110 BASE & STRUCTURE | B5: Mechanical | C5: Fabricated Part | D5: Not Finalized | E5: Buy | F5: Pcs
A6: 120 (rename) | B6: Electrical | C6: Std Mechanical | D6: Finalized – Not Purchased | E6: Make (Fabricate) | F6: Set
A7: 130 (rename) | B7: Pneumatic | C7: Pneumatic | D7: Purchased – Not Received | E7: Customer Supplied | F7: Mtr
A8: 140 (rename) | B8: Software / Vision | C8: Vacuum | D8: Received | F8: Lot
A9: 150 (rename) | B9: Others | C9: Motion / Actuator | D9: NSW Purchased | F9: Roll
A10: 160 (rename) | C10: Electrical / Control | D10: New Request to NSW
A11: 170 (rename) | C11: Sensor | D11: Cancelled
A12: 180 (rename) | C12: Vision
A13: 190 (rename) | C13: Safety
A14: 200 (rename) | C14: Consumable / Others
A15: 210 (rename)
A16: 220 (rename)
A17: 230 (rename)
A18: 240 (rename)
A19: 250 (rename)
